[2025-02-28T09:24:04.061+0000] {taskinstance.py:1159} INFO - Dependencies all met for dep_context=non-requeueable deps ti=<TaskInstance: customer_churn_ml_pipeline.data_ingestion_task manual__2025-02-28T09:23:57.532172+00:00 [queued]>
[2025-02-28T09:24:04.074+0000] {taskinstance.py:1159} INFO - Dependencies all met for dep_context=requeueable deps ti=<TaskInstance: customer_churn_ml_pipeline.data_ingestion_task manual__2025-02-28T09:23:57.532172+00:00 [queued]>
[2025-02-28T09:24:04.074+0000] {taskinstance.py:1361} INFO - Starting attempt 1 of 1
[2025-02-28T09:24:04.097+0000] {taskinstance.py:1382} INFO - Executing <Task(BashOperator): data_ingestion_task> on 2025-02-28 09:23:57.532172+00:00
[2025-02-28T09:24:04.102+0000] {standard_task_runner.py:57} INFO - Started process 10877 to run task
[2025-02-28T09:24:04.105+0000] {standard_task_runner.py:84} INFO - Running: ['***', 'tasks', 'run', 'customer_churn_ml_pipeline', 'data_ingestion_task', 'manual__2025-02-28T09:23:57.532172+00:00', '--job-id', '117', '--raw', '--subdir', 'DAGS_FOLDER/customer_churn.py', '--cfg-path', '/tmp/tmpv79tlsmq']
[2025-02-28T09:24:04.108+0000] {standard_task_runner.py:85} INFO - Job 117: Subtask data_ingestion_task
[2025-02-28T09:24:04.139+0000] {logging_mixin.py:154} WARNING - /home/***/.local/lib/python3.8/site-packages/***/settings.py:195 DeprecationWarning: The sql_alchemy_conn option in [core] has been moved to the sql_alchemy_conn option in [database] - the old setting has been used, but please update your config.
[2025-02-28T09:24:04.196+0000] {task_command.py:416} INFO - Running <TaskInstance: customer_churn_ml_pipeline.data_ingestion_task manual__2025-02-28T09:23:57.532172+00:00 [running]> on host 4470298645d8
[2025-02-28T09:24:04.330+0000] {taskinstance.py:1662} INFO - Exporting env vars: AIRFLOW_CTX_DAG_OWNER='***' AIRFLOW_CTX_DAG_ID='customer_churn_ml_pipeline' AIRFLOW_CTX_TASK_ID='data_ingestion_task' AIRFLOW_CTX_EXECUTION_DATE='2025-02-28T09:23:57.532172+00:00' AIRFLOW_CTX_TRY_NUMBER='1' AIRFLOW_CTX_DAG_RUN_ID='manual__2025-02-28T09:23:57.532172+00:00'
[2025-02-28T09:24:04.331+0000] {subprocess.py:63} INFO - Tmp dir root location: /tmp
[2025-02-28T09:24:04.332+0000] {subprocess.py:75} INFO - Running command: ['/bin/bash', '-c', 'python /opt/***/executables/data_ingestion.py && \t\t\tcd /opt/*** && \t\t\tgit rm -r --cached \'data/raw\'\n\t\t\tgit commit -m "stop tracking data/raw"\n                        dvc add /opt/***/data/raw &&                         git add /opt/***/data/raw.dvc &&                         git commit -m "Updated raw data version" -a &&                         dvc push && git push\n                    ']
[2025-02-28T09:24:04.342+0000] {subprocess.py:86} INFO - Output:
[2025-02-28T09:24:06.170+0000] {subprocess.py:93} INFO - /opt/***/executables/data_ingestion.py:46: UserWarning: pandas only supports SQLAlchemy connectable (engine/connection) or database string URI or sqlite3 DBAPI2 connection. Other DBAPI2 objects are not tested. Please consider using SQLAlchemy.
[2025-02-28T09:24:06.171+0000] {subprocess.py:93} INFO -   data = pd.read_sql(query, connection)
[2025-02-28T09:24:06.327+0000] {subprocess.py:93} INFO - fatal: pathspec 'data/raw' did not match any files
[2025-02-28T09:24:06.335+0000] {subprocess.py:93} INFO - On branch main
[2025-02-28T09:24:06.335+0000] {subprocess.py:93} INFO - Your branch is ahead of 'origin/main' by 1 commit.
[2025-02-28T09:24:06.336+0000] {subprocess.py:93} INFO -   (use "git push" to publish your local commits)
[2025-02-28T09:24:06.336+0000] {subprocess.py:93} INFO - 
[2025-02-28T09:24:06.336+0000] {subprocess.py:93} INFO - Changes not staged for commit:
[2025-02-28T09:24:06.336+0000] {subprocess.py:93} INFO -   (use "git add/rm <file>..." to update what will be committed)
[2025-02-28T09:24:06.337+0000] {subprocess.py:93} INFO -   (use "git restore <file>..." to discard changes in working directory)
[2025-02-28T09:24:06.337+0000] {subprocess.py:93} INFO - 	modified:   logs/dag_processor_manager/dag_processor_manager.log
[2025-02-28T09:24:06.337+0000] {subprocess.py:93} INFO - 	modified:   logs/data_ingestion.log
[2025-02-28T09:24:06.338+0000] {subprocess.py:93} INFO - 	deleted:    visualization/plots.pdf
[2025-02-28T09:24:06.338+0000] {subprocess.py:93} INFO - 
[2025-02-28T09:24:06.338+0000] {subprocess.py:93} INFO - Untracked files:
[2025-02-28T09:24:06.339+0000] {subprocess.py:93} INFO -   (use "git add <file>..." to include in what will be committed)
[2025-02-28T09:24:06.339+0000] {subprocess.py:93} INFO - 	data/.gitignore
[2025-02-28T09:24:06.339+0000] {subprocess.py:93} INFO - 	logs/dag_id=customer_churn_ml_pipeline/run_id=manual__2025-02-28T09:12:16.323386+00:00/
[2025-02-28T09:24:06.339+0000] {subprocess.py:93} INFO - 	logs/dag_id=customer_churn_ml_pipeline/run_id=manual__2025-02-28T09:19:35.565277+00:00/
[2025-02-28T09:24:06.340+0000] {subprocess.py:93} INFO - 	logs/dag_id=customer_churn_ml_pipeline/run_id=manual__2025-02-28T09:23:57.532172+00:00/
[2025-02-28T09:24:06.340+0000] {subprocess.py:93} INFO - 
[2025-02-28T09:24:06.340+0000] {subprocess.py:93} INFO - no changes added to commit (use "git add" and/or "git commit -a")
[2025-02-28T09:24:08.167+0000] {subprocess.py:93} INFO - 
[2025-02-28T09:24:08.168+0000] {subprocess.py:93} INFO - To track the changes with git, run:
[2025-02-28T09:24:08.168+0000] {subprocess.py:93} INFO - 
[2025-02-28T09:24:08.169+0000] {subprocess.py:93} INFO - 	git add data/raw.dvc
[2025-02-28T09:24:08.169+0000] {subprocess.py:93} INFO - 
[2025-02-28T09:24:08.169+0000] {subprocess.py:93} INFO - To enable auto staging, run:
[2025-02-28T09:24:08.169+0000] {subprocess.py:93} INFO - 
[2025-02-28T09:24:08.170+0000] {subprocess.py:93} INFO - 	dvc config core.autostage true
[2025-02-28T09:24:08.506+0000] {subprocess.py:93} INFO - error: insufficient permission for adding an object to repository database .git/objects
[2025-02-28T09:24:08.507+0000] {subprocess.py:93} INFO - error: insufficient permission for adding an object to repository database .git/objects
[2025-02-28T09:24:08.508+0000] {subprocess.py:93} INFO - error: Error building trees
[2025-02-28T09:24:08.508+0000] {subprocess.py:97} INFO - Command exited with return code 1
[2025-02-28T09:24:08.536+0000] {taskinstance.py:1937} ERROR - Task failed with exception
Traceback (most recent call last):
  File "/home/airflow/.local/lib/python3.8/site-packages/airflow/operators/bash.py", line 210, in execute
    raise AirflowException(
airflow.exceptions.AirflowException: Bash command failed. The command returned a non-zero exit code 1.
[2025-02-28T09:24:08.548+0000] {taskinstance.py:1400} INFO - Marking task as FAILED. dag_id=customer_churn_ml_pipeline, task_id=data_ingestion_task, execution_date=20250228T092357, start_date=20250228T092404, end_date=20250228T092408
[2025-02-28T09:24:08.573+0000] {standard_task_runner.py:104} ERROR - Failed to execute job 117 for task data_ingestion_task (Bash command failed. The command returned a non-zero exit code 1.; 10877)
[2025-02-28T09:24:08.618+0000] {local_task_job_runner.py:228} INFO - Task exited with return code 1
[2025-02-28T09:24:08.675+0000] {taskinstance.py:2778} INFO - 0 downstream tasks scheduled from follow-on schedule check
