[2025-03-03T16:41:37.534+0000] {taskinstance.py:1159} INFO - Dependencies all met for dep_context=non-requeueable deps ti=<TaskInstance: customer_churn_ml_pipeline.model_training_task manual__2025-03-03T16:39:59.268411+00:00 [queued]>
[2025-03-03T16:41:37.545+0000] {taskinstance.py:1159} INFO - Dependencies all met for dep_context=requeueable deps ti=<TaskInstance: customer_churn_ml_pipeline.model_training_task manual__2025-03-03T16:39:59.268411+00:00 [queued]>
[2025-03-03T16:41:37.545+0000] {taskinstance.py:1361} INFO - Starting attempt 1 of 1
[2025-03-03T16:41:37.563+0000] {taskinstance.py:1382} INFO - Executing <Task(BashOperator): model_training_task> on 2025-03-03 16:39:59.268411+00:00
[2025-03-03T16:41:37.568+0000] {standard_task_runner.py:57} INFO - Started process 4842 to run task
[2025-03-03T16:41:37.571+0000] {standard_task_runner.py:84} INFO - Running: ['***', 'tasks', 'run', 'customer_churn_ml_pipeline', 'model_training_task', 'manual__2025-03-03T16:39:59.268411+00:00', '--job-id', '107', '--raw', '--subdir', 'DAGS_FOLDER/customer_churn.py', '--cfg-path', '/tmp/tmpzixyu5iy']
[2025-03-03T16:41:37.574+0000] {standard_task_runner.py:85} INFO - Job 107: Subtask model_training_task
[2025-03-03T16:41:37.595+0000] {logging_mixin.py:154} WARNING - /home/***/.local/lib/python3.8/site-packages/***/settings.py:195 DeprecationWarning: The sql_alchemy_conn option in [core] has been moved to the sql_alchemy_conn option in [database] - the old setting has been used, but please update your config.
[2025-03-03T16:41:37.638+0000] {task_command.py:416} INFO - Running <TaskInstance: customer_churn_ml_pipeline.model_training_task manual__2025-03-03T16:39:59.268411+00:00 [running]> on host 157237bff8f7
[2025-03-03T16:41:37.760+0000] {taskinstance.py:1662} INFO - Exporting env vars: AIRFLOW_CTX_DAG_OWNER='***' AIRFLOW_CTX_DAG_ID='customer_churn_ml_pipeline' AIRFLOW_CTX_TASK_ID='model_training_task' AIRFLOW_CTX_EXECUTION_DATE='2025-03-03T16:39:59.268411+00:00' AIRFLOW_CTX_TRY_NUMBER='1' AIRFLOW_CTX_DAG_RUN_ID='manual__2025-03-03T16:39:59.268411+00:00'
[2025-03-03T16:41:37.761+0000] {subprocess.py:63} INFO - Tmp dir root location: /tmp
[2025-03-03T16:41:37.762+0000] {subprocess.py:75} INFO - Running command: ['/bin/bash', '-c', '\n\t    \t\tcd /opt/***\n       \t\t\t    python /opt/***/executables/model_training.py && \t      \t\t    git add logs && \t      \t\t    git add mlruns && \t        \t    git status &&                             git commit -m "Trained model version" -a && \\    \n\t\t\t    git push\n                        ']
[2025-03-03T16:41:37.772+0000] {subprocess.py:86} INFO - Output:
[2025-03-03T16:41:43.991+0000] {subprocess.py:93} INFO - /home/***/.local/lib/python3.8/site-packages/mlflow/gateway/config.py:64: PydanticDeprecatedSince20: Pydantic V1 style `@validator` validators are deprecated. You should migrate to Pydantic V2 style `@field_validator` validators, see the migration guide for more details. Deprecated in Pydantic V2.0 to be removed in V3.0. See Pydantic V2 Migration Guide at https://errors.pydantic.dev/2.4/migration/
[2025-03-03T16:41:43.991+0000] {subprocess.py:93} INFO -   @validator("togetherai_api_key", pre=True)
[2025-03-03T16:41:43.991+0000] {subprocess.py:93} INFO - /home/***/.local/lib/python3.8/site-packages/mlflow/gateway/config.py:372: PydanticDeprecatedSince20: Pydantic V1 style `@root_validator` validators are deprecated. You should migrate to Pydantic V2 style `@model_validator` validators, see the migration guide for more details. Deprecated in Pydantic V2.0 to be removed in V3.0. See Pydantic V2 Migration Guide at https://errors.pydantic.dev/2.4/migration/
[2025-03-03T16:41:43.992+0000] {subprocess.py:93} INFO -   @root_validator(skip_on_failure=True)
[2025-03-03T16:41:43.992+0000] {subprocess.py:93} INFO - /home/***/.local/lib/python3.8/site-packages/pydantic/_internal/_config.py:267: PydanticDeprecatedSince20: Support for class-based `config` is deprecated, use ConfigDict instead. Deprecated in Pydantic V2.0 to be removed in V3.0. See Pydantic V2 Migration Guide at https://errors.pydantic.dev/2.4/migration/
[2025-03-03T16:41:43.992+0000] {subprocess.py:93} INFO -   warnings.warn(DEPRECATION_MESSAGE, DeprecationWarning)
[2025-03-03T16:41:43.992+0000] {subprocess.py:93} INFO - 2025-03-03 16:41:43,990 : INFO : Starting model training
[2025-03-03T16:41:44.009+0000] {subprocess.py:93} INFO - 2025-03-03 16:41:44,009 : INFO : Registry cache expired, so refreshing
[2025-03-03T16:41:44.018+0000] {subprocess.py:93} INFO - 2025-03-03 16:41:44,018 : INFO : Getting data
[2025-03-03T16:41:44.019+0000] {subprocess.py:93} INFO - 2025-03-03 16:41:44,019 : INFO : Start and End Range: 1 to 1000
[2025-03-03T16:41:44.388+0000] {subprocess.py:93} INFO - 2025-03-03 16:41:44,387 : INFO : Data fetched: 999
[2025-03-03T16:41:44.388+0000] {subprocess.py:93} INFO - 2025-03-03 16:41:44,388 : INFO : New Start and End Range: 1001 to 2000
[2025-03-03T16:41:44.388+0000] {subprocess.py:93} INFO - 2025-03-03 16:41:44,388 : INFO : Start and End Range: 1001 to 2000
[2025-03-03T16:41:44.646+0000] {subprocess.py:93} INFO - 2025-03-03 16:41:44,646 : INFO : Data fetched: 999
[2025-03-03T16:41:44.647+0000] {subprocess.py:93} INFO - 2025-03-03 16:41:44,646 : INFO : New Start and End Range: 3001 to 4000
[2025-03-03T16:41:44.647+0000] {subprocess.py:93} INFO - 2025-03-03 16:41:44,647 : INFO : Start and End Range: 3001 to 4000
[2025-03-03T16:41:45.006+0000] {subprocess.py:93} INFO - 2025-03-03 16:41:45,005 : INFO : Data fetched: 999
[2025-03-03T16:41:45.006+0000] {subprocess.py:93} INFO - 2025-03-03 16:41:45,006 : INFO : New Start and End Range: 7001 to 8000
[2025-03-03T16:41:45.006+0000] {subprocess.py:93} INFO - 2025-03-03 16:41:45,006 : INFO : Start and End Range: 7001 to 8000
[2025-03-03T16:41:45.289+0000] {subprocess.py:93} INFO - 2025-03-03 16:41:45,289 : INFO : Data fetched: 999
[2025-03-03T16:41:45.290+0000] {subprocess.py:93} INFO - 2025-03-03 16:41:45,289 : INFO : New Start and End Range: 15001 to 16000
[2025-03-03T16:41:45.290+0000] {subprocess.py:93} INFO - 2025-03-03 16:41:45,290 : INFO : Start and End Range: 15001 to 16000
[2025-03-03T16:41:45.646+0000] {subprocess.py:93} INFO - 2025-03-03 16:41:45,646 : INFO : Data fetched: 999
[2025-03-03T16:41:45.647+0000] {subprocess.py:93} INFO - 2025-03-03 16:41:45,646 : INFO : New Start and End Range: 31001 to 32000
[2025-03-03T16:41:45.647+0000] {subprocess.py:93} INFO - 2025-03-03 16:41:45,647 : INFO : Start and End Range: 31001 to 32000
[2025-03-03T16:41:45.726+0000] {subprocess.py:93} INFO - 2025-03-03 16:41:45,725 : INFO : Reached End of Data
[2025-03-03T16:41:45.728+0000] {subprocess.py:93} INFO - 2025-03-03 16:41:45,728 : INFO : Stoping at Start and End Range: 31001 to 32000
[2025-03-03T16:41:45.729+0000] {subprocess.py:93} INFO - 2025-03-03 16:41:45,728 : INFO : Created feature data
[2025-03-03T16:41:45.729+0000] {subprocess.py:93} INFO - 2025-03-03 16:41:45,728 : INFO : Total Data fetched: 5
[2025-03-03T16:41:45.733+0000] {subprocess.py:93} INFO - 2025-03-03 16:41:45,733 : INFO : received feature data
[2025-03-03T16:41:45.737+0000] {subprocess.py:93} INFO - 2025-03-03 16:41:45,737 : INFO : Models defined
[2025-03-03T16:41:45.737+0000] {subprocess.py:93} INFO - 2025-03-03 16:41:45,737 : INFO : Training model RandomForest
[2025-03-03T16:41:46.798+0000] {subprocess.py:93} INFO - 2025-03-03 16:41:46,798 : INFO : Predicting model RandomForest
[2025-03-03T16:41:46.824+0000] {subprocess.py:93} INFO - 2025-03-03 16:41:46,824 : INFO : Calculating accuracy RandomForest
[2025-03-03T16:41:46.973+0000] {subprocess.py:93} INFO - 2025-03-03 16:41:46,972 : WARNING : Retrying (JitteredRetry(total=4, connect=4, read=5, redirect=5, status=5)) after connection broken by 'NewConnectionError('<urllib3.connection.HTTPConnection object at 0x7f5417d122e0>: Failed to establish a new connection: [Errno 111] Connection refused')': /api/2.0/mlflow/runs/create
[2025-03-03T16:41:50.979+0000] {subprocess.py:93} INFO - 2025-03-03 16:41:50,978 : WARNING : Retrying (JitteredRetry(total=3, connect=3, read=5, redirect=5, status=5)) after connection broken by 'NewConnectionError('<urllib3.connection.HTTPConnection object at 0x7f5417d12280>: Failed to establish a new connection: [Errno 111] Connection refused')': /api/2.0/mlflow/runs/create
[2025-03-03T16:41:58.991+0000] {subprocess.py:93} INFO - 2025-03-03 16:41:58,990 : WARNING : Retrying (JitteredRetry(total=2, connect=2, read=5, redirect=5, status=5)) after connection broken by 'NewConnectionError('<urllib3.connection.HTTPConnection object at 0x7f5417d12a00>: Failed to establish a new connection: [Errno 111] Connection refused')': /api/2.0/mlflow/runs/create
[2025-03-03T16:42:15.006+0000] {subprocess.py:93} INFO - 2025-03-03 16:42:15,005 : WARNING : Retrying (JitteredRetry(total=1, connect=1, read=5, redirect=5, status=5)) after connection broken by 'NewConnectionError('<urllib3.connection.HTTPConnection object at 0x7f5417d12970>: Failed to establish a new connection: [Errno 111] Connection refused')': /api/2.0/mlflow/runs/create
[2025-03-03T16:42:47.024+0000] {subprocess.py:93} INFO - 2025-03-03 16:42:47,023 : WARNING : Retrying (JitteredRetry(total=0, connect=0, read=5, redirect=5, status=5)) after connection broken by 'NewConnectionError('<urllib3.connection.HTTPConnection object at 0x7f5417d3ba60>: Failed to establish a new connection: [Errno 111] Connection refused')': /api/2.0/mlflow/runs/create
[2025-03-03T16:42:47.025+0000] {subprocess.py:93} INFO - Error in model training: API request to http://localhost:5000/api/2.0/mlflow/runs/create failed with exception HTTPConnectionPool(host='localhost', port=5000): Max retries exceeded with url: /api/2.0/mlflow/runs/create (Caused by NewConnectionError('<urllib3.connection.HTTPConnection object at 0x7f5417d3bc10>: Failed to establish a new connection: [Errno 111] Connection refused'))
[2025-03-03T16:42:47.574+0000] {subprocess.py:93} INFO - On branch main
[2025-03-03T16:42:47.574+0000] {subprocess.py:93} INFO - Your branch is up to date with 'origin/main'.
[2025-03-03T16:42:47.574+0000] {subprocess.py:93} INFO - 
[2025-03-03T16:42:47.575+0000] {subprocess.py:93} INFO - Changes to be committed:
[2025-03-03T16:42:47.575+0000] {subprocess.py:93} INFO -   (use "git restore --staged <file>..." to unstage)
[2025-03-03T16:42:47.575+0000] {subprocess.py:93} INFO - 	modified:   logs/dag_id=customer_churn_ml_pipeline/run_id=manual__2025-03-03T16:39:59.268411+00:00/task_id=feature_store_task/attempt=1.log
[2025-03-03T16:42:47.575+0000] {subprocess.py:93} INFO - 	new file:   logs/dag_id=customer_churn_ml_pipeline/run_id=manual__2025-03-03T16:39:59.268411+00:00/task_id=model_training_task/attempt=1.log
[2025-03-03T16:42:47.575+0000] {subprocess.py:93} INFO - 	modified:   logs/dag_processor_manager/dag_processor_manager.log
[2025-03-03T16:42:47.576+0000] {subprocess.py:93} INFO - 	modified:   logs/model_training.log
[2025-03-03T16:42:47.576+0000] {subprocess.py:93} INFO - 	modified:   logs/scheduler/2025-03-03/customer_churn.py.log
[2025-03-03T16:42:47.576+0000] {subprocess.py:93} INFO - 
[2025-03-03T16:42:47.576+0000] {subprocess.py:93} INFO - Untracked files:
[2025-03-03T16:42:47.576+0000] {subprocess.py:93} INFO -   (use "git add <file>..." to include in what will be committed)
[2025-03-03T16:42:47.576+0000] {subprocess.py:93} INFO - 	customer_churn_stats/feature_repo/data/online_store.db
[2025-03-03T16:42:47.577+0000] {subprocess.py:93} INFO - 	customer_churn_stats/feature_repo/data/registry.db
[2025-03-03T16:42:47.577+0000] {subprocess.py:93} INFO - 	models/
[2025-03-03T16:42:47.577+0000] {subprocess.py:93} INFO - 	online.db
[2025-03-03T16:42:47.577+0000] {subprocess.py:93} INFO - 
