[2025-03-02T15:36:15.504+0000] {taskinstance.py:1159} INFO - Dependencies all met for dep_context=non-requeueable deps ti=<TaskInstance: customer_churn_ml_pipeline.data_validation_task manual__2025-03-02T15:34:31.306444+00:00 [queued]>
[2025-03-02T15:36:15.514+0000] {taskinstance.py:1159} INFO - Dependencies all met for dep_context=requeueable deps ti=<TaskInstance: customer_churn_ml_pipeline.data_validation_task manual__2025-03-02T15:34:31.306444+00:00 [queued]>
[2025-03-02T15:36:15.514+0000] {taskinstance.py:1361} INFO - Starting attempt 1 of 1
[2025-03-02T15:36:15.531+0000] {taskinstance.py:1382} INFO - Executing <Task(BashOperator): data_validation_task> on 2025-03-02 15:34:31.306444+00:00
[2025-03-02T15:36:15.535+0000] {standard_task_runner.py:57} INFO - Started process 3179 to run task
[2025-03-02T15:36:15.540+0000] {standard_task_runner.py:84} INFO - Running: ['***', 'tasks', 'run', 'customer_churn_ml_pipeline', 'data_validation_task', 'manual__2025-03-02T15:34:31.306444+00:00', '--job-id', '60', '--raw', '--subdir', 'DAGS_FOLDER/customer_churn.py', '--cfg-path', '/tmp/tmpnu38stbu']
[2025-03-02T15:36:15.544+0000] {standard_task_runner.py:85} INFO - Job 60: Subtask data_validation_task
[2025-03-02T15:36:15.570+0000] {logging_mixin.py:154} WARNING - /home/***/.local/lib/python3.8/site-packages/***/settings.py:195 DeprecationWarning: The sql_alchemy_conn option in [core] has been moved to the sql_alchemy_conn option in [database] - the old setting has been used, but please update your config.
[2025-03-02T15:36:15.630+0000] {task_command.py:416} INFO - Running <TaskInstance: customer_churn_ml_pipeline.data_validation_task manual__2025-03-02T15:34:31.306444+00:00 [running]> on host 157237bff8f7
[2025-03-02T15:36:15.770+0000] {taskinstance.py:1662} INFO - Exporting env vars: AIRFLOW_CTX_DAG_OWNER='***' AIRFLOW_CTX_DAG_ID='customer_churn_ml_pipeline' AIRFLOW_CTX_TASK_ID='data_validation_task' AIRFLOW_CTX_EXECUTION_DATE='2025-03-02T15:34:31.306444+00:00' AIRFLOW_CTX_TRY_NUMBER='1' AIRFLOW_CTX_DAG_RUN_ID='manual__2025-03-02T15:34:31.306444+00:00'
[2025-03-02T15:36:15.771+0000] {subprocess.py:63} INFO - Tmp dir root location: /tmp
[2025-03-02T15:36:15.772+0000] {subprocess.py:75} INFO - Running command: ['/bin/bash', '-c', '\n\t\t\tcd /opt/*** &&                        dvc pull /opt/***/data/raw\n                        python /opt/***/executables/data_validation.py && \t\t\tgit add logs && \\   \n\t\t\tgit add reports &&    \t\t\tgit status &&                         git commit -m "Updated validation" -a &&                         dvc push && git push\n                    ']
[2025-03-02T15:36:15.779+0000] {subprocess.py:86} INFO - Output:
[2025-03-02T15:36:18.988+0000] {subprocess.py:93} INFO - Everything is up to date.
[2025-03-02T15:36:20.117+0000] {subprocess.py:93} INFO - 2025-03-02 15:36:20,116 : INFO : Starting data validation
[2025-03-02T15:36:20.133+0000] {subprocess.py:93} INFO - 2025-03-02 15:36:20,133 : INFO : Running validation on data received from S3
[2025-03-02T15:36:20.206+0000] {subprocess.py:93} INFO - 2025-03-02 15:36:20,206 : INFO : Saving metrics to S3
[2025-03-02T15:36:20.208+0000] {subprocess.py:93} INFO - 2025-03-02 15:36:20,208 : INFO : Metrics saved to: csv_validation_report.csv
[2025-03-02T15:36:20.337+0000] {subprocess.py:93} INFO - /bin/bash: line 3:  : command not found
[2025-03-02T15:36:20.358+0000] {subprocess.py:93} INFO - On branch main
[2025-03-02T15:36:20.358+0000] {subprocess.py:93} INFO - Your branch is up to date with 'origin/main'.
[2025-03-02T15:36:20.358+0000] {subprocess.py:93} INFO - 
[2025-03-02T15:36:20.359+0000] {subprocess.py:93} INFO - Changes to be committed:
[2025-03-02T15:36:20.359+0000] {subprocess.py:93} INFO -   (use "git restore --staged <file>..." to unstage)
[2025-03-02T15:36:20.359+0000] {subprocess.py:93} INFO - 	new file:   logs/dag_id=customer_churn_ml_pipeline/run_id=manual__2025-03-02T15:34:31.306444+00:00/task_id=data_validation_task/attempt=1.log
[2025-03-02T15:36:20.359+0000] {subprocess.py:93} INFO - 	modified:   logs/dag_id=customer_churn_ml_pipeline/run_id=manual__2025-03-02T15:34:31.306444+00:00/task_id=raw_data_storage_task/attempt=1.log
[2025-03-02T15:36:20.359+0000] {subprocess.py:93} INFO - 	modified:   logs/dag_processor_manager/dag_processor_manager.log
[2025-03-02T15:36:20.359+0000] {subprocess.py:93} INFO - 	modified:   logs/data_validation.log
[2025-03-02T15:36:20.360+0000] {subprocess.py:93} INFO - 	modified:   logs/scheduler/2025-03-02/customer_churn.py.log
[2025-03-02T15:36:20.360+0000] {subprocess.py:93} INFO - 
[2025-03-02T15:36:20.360+0000] {subprocess.py:93} INFO - Changes not staged for commit:
[2025-03-02T15:36:20.360+0000] {subprocess.py:93} INFO -   (use "git add <file>..." to update what will be committed)
[2025-03-02T15:36:20.360+0000] {subprocess.py:93} INFO -   (use "git restore <file>..." to discard changes in working directory)
[2025-03-02T15:36:20.360+0000] {subprocess.py:93} INFO - 	modified:   logs/dag_id=customer_churn_ml_pipeline/run_id=manual__2025-03-02T15:34:31.306444+00:00/task_id=data_validation_task/attempt=1.log
[2025-03-02T15:36:20.360+0000] {subprocess.py:93} INFO - 
[2025-03-02T15:36:20.360+0000] {subprocess.py:93} INFO - Untracked files:
[2025-03-02T15:36:20.361+0000] {subprocess.py:93} INFO -   (use "git add <file>..." to include in what will be committed)
[2025-03-02T15:36:20.361+0000] {subprocess.py:93} INFO - 	customer_churn_stats/feature_repo/data/online_store.db
[2025-03-02T15:36:20.361+0000] {subprocess.py:93} INFO - 	customer_churn_stats/feature_repo/data/registry.db
[2025-03-02T15:36:20.361+0000] {subprocess.py:93} INFO - 	mlruns/mlruns/mlruns/mlruns/
[2025-03-02T15:36:20.361+0000] {subprocess.py:93} INFO - 	online.db
[2025-03-02T15:36:20.361+0000] {subprocess.py:93} INFO - 
[2025-03-02T15:36:20.409+0000] {subprocess.py:93} INFO - [main 50c357c] Updated validation
[2025-03-02T15:36:20.410+0000] {subprocess.py:93} INFO -  5 files changed, 71 insertions(+)
[2025-03-02T15:36:20.410+0000] {subprocess.py:93} INFO -  create mode 100644 logs/dag_id=customer_churn_ml_pipeline/run_id=manual__2025-03-02T15:34:31.306444+00:00/task_id=data_validation_task/attempt=1.log
[2025-03-02T15:36:24.800+0000] {subprocess.py:93} INFO - Everything is up to date.
[2025-03-02T15:36:26.661+0000] {subprocess.py:93} INFO - To https://github.com/anniemathew-trial/customer_churn_pipeline.git
[2025-03-02T15:36:26.662+0000] {subprocess.py:93} INFO -    1351e0c..50c357c  main -> main
[2025-03-02T15:36:26.677+0000] {subprocess.py:97} INFO - Command exited with return code 0
[2025-03-02T15:36:26.725+0000] {taskinstance.py:1400} INFO - Marking task as SUCCESS. dag_id=customer_churn_ml_pipeline, task_id=data_validation_task, execution_date=20250302T153431, start_date=20250302T153615, end_date=20250302T153626
[2025-03-02T15:36:26.752+0000] {local_task_job_runner.py:228} INFO - Task exited with return code 0
[2025-03-02T15:36:26.790+0000] {taskinstance.py:2778} INFO - 1 downstream tasks scheduled from follow-on schedule check
