[2025-03-02T06:34:30.161+0000] {taskinstance.py:1159} INFO - Dependencies all met for dep_context=non-requeueable deps ti=<TaskInstance: customer_churn_ml_pipeline.data_validation_task manual__2025-03-02T06:33:39.020792+00:00 [queued]>
[2025-03-02T06:34:30.176+0000] {taskinstance.py:1159} INFO - Dependencies all met for dep_context=requeueable deps ti=<TaskInstance: customer_churn_ml_pipeline.data_validation_task manual__2025-03-02T06:33:39.020792+00:00 [queued]>
[2025-03-02T06:34:30.177+0000] {taskinstance.py:1361} INFO - Starting attempt 1 of 1
[2025-03-02T06:34:30.201+0000] {taskinstance.py:1382} INFO - Executing <Task(BashOperator): data_validation_task> on 2025-03-02 06:33:39.020792+00:00
[2025-03-02T06:34:30.207+0000] {standard_task_runner.py:57} INFO - Started process 4351 to run task
[2025-03-02T06:34:30.211+0000] {standard_task_runner.py:84} INFO - Running: ['***', 'tasks', 'run', 'customer_churn_ml_pipeline', 'data_validation_task', 'manual__2025-03-02T06:33:39.020792+00:00', '--job-id', '254', '--raw', '--subdir', 'DAGS_FOLDER/customer_churn.py', '--cfg-path', '/tmp/tmpiz3vgggn']
[2025-03-02T06:34:30.215+0000] {standard_task_runner.py:85} INFO - Job 254: Subtask data_validation_task
[2025-03-02T06:34:30.246+0000] {logging_mixin.py:154} WARNING - /home/***/.local/lib/python3.8/site-packages/***/settings.py:195 DeprecationWarning: The sql_alchemy_conn option in [core] has been moved to the sql_alchemy_conn option in [database] - the old setting has been used, but please update your config.
[2025-03-02T06:34:30.309+0000] {task_command.py:416} INFO - Running <TaskInstance: customer_churn_ml_pipeline.data_validation_task manual__2025-03-02T06:33:39.020792+00:00 [running]> on host 7e994a0ed489
[2025-03-02T06:34:30.468+0000] {taskinstance.py:1662} INFO - Exporting env vars: AIRFLOW_CTX_DAG_OWNER='***' AIRFLOW_CTX_DAG_ID='customer_churn_ml_pipeline' AIRFLOW_CTX_TASK_ID='data_validation_task' AIRFLOW_CTX_EXECUTION_DATE='2025-03-02T06:33:39.020792+00:00' AIRFLOW_CTX_TRY_NUMBER='1' AIRFLOW_CTX_DAG_RUN_ID='manual__2025-03-02T06:33:39.020792+00:00'
[2025-03-02T06:34:30.469+0000] {subprocess.py:63} INFO - Tmp dir root location: /tmp
[2025-03-02T06:34:30.470+0000] {subprocess.py:75} INFO - Running command: ['/bin/bash', '-c', '\n\t\t\tNOW=$(date \'+%d-%m-%Y\') &&\t\t\tcd /opt/*** &&                        dvc pull /opt/***/data/raw\n                        python /opt/***/executables/data_validation.py && \t\t\tgit add logs &&\\   \n\t\t\tgit add reports &&                        git commit -m "Updated validation" -a &&                         dvc push && git push\n                    ']
[2025-03-02T06:34:30.482+0000] {subprocess.py:86} INFO - Output:
[2025-03-02T06:34:32.735+0000] {subprocess.py:93} INFO - WARNING: failed to collect 'workspace', skipping
[2025-03-02T06:34:32.736+0000] {subprocess.py:93} INFO - ERROR: failed to pull data from the cloud - '/opt/***/data/raw' does not exist as an output or a stage name in 'dvc.yaml': 'dvc.yaml' does not exist
[2025-03-02T06:34:34.802+0000] {subprocess.py:93} INFO - 2025-03-02 06:34:34,801 : INFO : Starting data validation
[2025-03-02T06:34:34.803+0000] {subprocess.py:93} INFO - 2025-03-02 06:34:34,802 : ERROR : Error validating  data: [Errno 2] No such file or directory: 'data/raw/customer_data.csv'
[2025-03-02T06:34:34.803+0000] {subprocess.py:93} INFO - Traceback (most recent call last):
[2025-03-02T06:34:34.804+0000] {subprocess.py:93} INFO -   File "/opt/***/executables/data_validation.py", line 87, in <module>
[2025-03-02T06:34:34.804+0000] {subprocess.py:93} INFO -     generate_csv_data_quality_report("customer_data.csv")
[2025-03-02T06:34:34.804+0000] {subprocess.py:93} INFO -   File "/opt/***/executables/data_validation.py", line 74, in generate_csv_data_quality_report
[2025-03-02T06:34:34.805+0000] {subprocess.py:93} INFO -     report_df = pd.DataFrame(report_data, columns=[
[2025-03-02T06:34:34.805+0000] {subprocess.py:93} INFO - UnboundLocalError: local variable 'report_data' referenced before assignment
[2025-03-02T06:34:35.028+0000] {subprocess.py:93} INFO - [main 0254494] Updated validation
[2025-03-02T06:34:35.029+0000] {subprocess.py:93} INFO -  3 files changed, 17 insertions(+)
[2025-03-02T06:34:40.915+0000] {subprocess.py:93} INFO - Everything is up to date.
[2025-03-02T06:34:42.645+0000] {subprocess.py:93} INFO - To https://github.com/anniemathew-trial/customer_churn_pipeline.git
[2025-03-02T06:34:42.645+0000] {subprocess.py:93} INFO -    3ba0931..0254494  main -> main
[2025-03-02T06:34:42.651+0000] {subprocess.py:97} INFO - Command exited with return code 0
[2025-03-02T06:34:42.695+0000] {taskinstance.py:1400} INFO - Marking task as SUCCESS. dag_id=customer_churn_ml_pipeline, task_id=data_validation_task, execution_date=20250302T063339, start_date=20250302T063430, end_date=20250302T063442
[2025-03-02T06:34:42.751+0000] {local_task_job_runner.py:228} INFO - Task exited with return code 0
[2025-03-02T06:34:42.800+0000] {taskinstance.py:2778} INFO - 1 downstream tasks scheduled from follow-on schedule check
