[2025-03-02T10:13:09.783+0000] {taskinstance.py:1159} INFO - Dependencies all met for dep_context=non-requeueable deps ti=<TaskInstance: customer_churn_ml_pipeline.data_transformation_task manual__2025-03-02T10:12:15.902148+00:00 [queued]>
[2025-03-02T10:13:09.796+0000] {taskinstance.py:1159} INFO - Dependencies all met for dep_context=requeueable deps ti=<TaskInstance: customer_churn_ml_pipeline.data_transformation_task manual__2025-03-02T10:12:15.902148+00:00 [queued]>
[2025-03-02T10:13:09.796+0000] {taskinstance.py:1361} INFO - Starting attempt 1 of 1
[2025-03-02T10:13:09.817+0000] {taskinstance.py:1382} INFO - Executing <Task(BashOperator): data_transformation_task> on 2025-03-02 10:12:15.902148+00:00
[2025-03-02T10:13:09.821+0000] {standard_task_runner.py:57} INFO - Started process 10229 to run task
[2025-03-02T10:13:09.826+0000] {standard_task_runner.py:84} INFO - Running: ['***', 'tasks', 'run', 'customer_churn_ml_pipeline', 'data_transformation_task', 'manual__2025-03-02T10:12:15.902148+00:00', '--job-id', '138', '--raw', '--subdir', 'DAGS_FOLDER/customer_churn.py', '--cfg-path', '/tmp/tmpgdwoq5ro']
[2025-03-02T10:13:09.829+0000] {standard_task_runner.py:85} INFO - Job 138: Subtask data_transformation_task
[2025-03-02T10:13:09.855+0000] {logging_mixin.py:154} WARNING - /home/***/.local/lib/python3.8/site-packages/***/settings.py:195 DeprecationWarning: The sql_alchemy_conn option in [core] has been moved to the sql_alchemy_conn option in [database] - the old setting has been used, but please update your config.
[2025-03-02T10:13:09.910+0000] {task_command.py:416} INFO - Running <TaskInstance: customer_churn_ml_pipeline.data_transformation_task manual__2025-03-02T10:12:15.902148+00:00 [running]> on host 9113a5746a05
[2025-03-02T10:13:10.044+0000] {taskinstance.py:1662} INFO - Exporting env vars: AIRFLOW_CTX_DAG_OWNER='***' AIRFLOW_CTX_DAG_ID='customer_churn_ml_pipeline' AIRFLOW_CTX_TASK_ID='data_transformation_task' AIRFLOW_CTX_EXECUTION_DATE='2025-03-02T10:12:15.902148+00:00' AIRFLOW_CTX_TRY_NUMBER='1' AIRFLOW_CTX_DAG_RUN_ID='manual__2025-03-02T10:12:15.902148+00:00'
[2025-03-02T10:13:10.046+0000] {subprocess.py:63} INFO - Tmp dir root location: /tmp
[2025-03-02T10:13:10.047+0000] {subprocess.py:75} INFO - Running command: ['/bin/bash', '-c', '\n\t\t\tcd /opt/*** &&                        dvc pull /opt/***/data/cleaned\n                        python /opt/***/executables/data_transformation.py &&                         dvc add /opt/***/data/transformed &&                         git add /opt/***/data/transformed.dvc && \t\t\tgit add logs &&    \t\t\tgit status &&                         git commit -m "Updated transformed data version" -a &&                         dvc push && git push\n                    ']
[2025-03-02T10:13:10.057+0000] {subprocess.py:86} INFO - Output:
[2025-03-02T10:13:13.279+0000] {subprocess.py:93} INFO - M       data/cleaned/
[2025-03-02T10:13:13.281+0000] {subprocess.py:93} INFO - 1 file modified
[2025-03-02T10:13:15.966+0000] {subprocess.py:93} INFO - 2025-03-02 10:13:15,965 : INFO : Starting data transformation for csv.
[2025-03-02T10:13:15.967+0000] {subprocess.py:93} INFO - 2025-03-02 10:13:15,966 : ERROR : Failed data transformation: [Errno 2] No such file or directory: '/opt/***/data/cleaned/02-03-2025/csv/customer_data.csv'
[2025-03-02T10:13:18.088+0000] {subprocess.py:93} INFO - ERROR: output 'data/transformed' does not exist: [Errno 2] No such file or directory: '/opt/***/data/transformed'
[2025-03-02T10:13:18.347+0000] {subprocess.py:97} INFO - Command exited with return code 1
[2025-03-02T10:13:18.367+0000] {taskinstance.py:1937} ERROR - Task failed with exception
Traceback (most recent call last):
  File "/home/airflow/.local/lib/python3.8/site-packages/airflow/operators/bash.py", line 210, in execute
    raise AirflowException(
airflow.exceptions.AirflowException: Bash command failed. The command returned a non-zero exit code 1.
[2025-03-02T10:13:18.372+0000] {taskinstance.py:1400} INFO - Marking task as FAILED. dag_id=customer_churn_ml_pipeline, task_id=data_transformation_task, execution_date=20250302T101215, start_date=20250302T101309, end_date=20250302T101318
[2025-03-02T10:13:18.393+0000] {standard_task_runner.py:104} ERROR - Failed to execute job 138 for task data_transformation_task (Bash command failed. The command returned a non-zero exit code 1.; 10229)
[2025-03-02T10:13:18.439+0000] {local_task_job_runner.py:228} INFO - Task exited with return code 1
[2025-03-02T10:13:18.504+0000] {taskinstance.py:2778} INFO - 0 downstream tasks scheduled from follow-on schedule check
