[2025-02-28T04:07:52.106+0000] {taskinstance.py:1159} INFO - Dependencies all met for dep_context=non-requeueable deps ti=<TaskInstance: customer_churn_ml_pipeline.data_ingestion_task manual__2025-02-28T04:07:47.368418+00:00 [queued]>
[2025-02-28T04:07:52.125+0000] {taskinstance.py:1159} INFO - Dependencies all met for dep_context=requeueable deps ti=<TaskInstance: customer_churn_ml_pipeline.data_ingestion_task manual__2025-02-28T04:07:47.368418+00:00 [queued]>
[2025-02-28T04:07:52.126+0000] {taskinstance.py:1361} INFO - Starting attempt 1 of 1
[2025-02-28T04:07:52.163+0000] {taskinstance.py:1382} INFO - Executing <Task(BashOperator): data_ingestion_task> on 2025-02-28 04:07:47.368418+00:00
[2025-02-28T04:07:52.169+0000] {standard_task_runner.py:57} INFO - Started process 6557 to run task
[2025-02-28T04:07:52.174+0000] {standard_task_runner.py:84} INFO - Running: ['***', 'tasks', 'run', 'customer_churn_ml_pipeline', 'data_ingestion_task', 'manual__2025-02-28T04:07:47.368418+00:00', '--job-id', '22', '--raw', '--subdir', 'DAGS_FOLDER/customer_churn.py', '--cfg-path', '/tmp/tmphh4xpyz1']
[2025-02-28T04:07:52.179+0000] {standard_task_runner.py:85} INFO - Job 22: Subtask data_ingestion_task
[2025-02-28T04:07:52.213+0000] {logging_mixin.py:154} WARNING - /home/***/.local/lib/python3.8/site-packages/***/settings.py:195 DeprecationWarning: The sql_alchemy_conn option in [core] has been moved to the sql_alchemy_conn option in [database] - the old setting has been used, but please update your config.
[2025-02-28T04:07:52.293+0000] {task_command.py:416} INFO - Running <TaskInstance: customer_churn_ml_pipeline.data_ingestion_task manual__2025-02-28T04:07:47.368418+00:00 [running]> on host 4470298645d8
[2025-02-28T04:07:52.460+0000] {taskinstance.py:1662} INFO - Exporting env vars: AIRFLOW_CTX_DAG_OWNER='***' AIRFLOW_CTX_DAG_ID='customer_churn_ml_pipeline' AIRFLOW_CTX_TASK_ID='data_ingestion_task' AIRFLOW_CTX_EXECUTION_DATE='2025-02-28T04:07:47.368418+00:00' AIRFLOW_CTX_TRY_NUMBER='1' AIRFLOW_CTX_DAG_RUN_ID='manual__2025-02-28T04:07:47.368418+00:00'
[2025-02-28T04:07:52.462+0000] {subprocess.py:63} INFO - Tmp dir root location: /tmp
[2025-02-28T04:07:52.463+0000] {subprocess.py:75} INFO - Running command: ['/bin/bash', '-c', 'python /opt/***/executables/data_ingestion.py && \t\t\tcd /opt/*** && \t\t\tgit rm -r --cached \'data/raw\'\n\t\t\tgit commit -m "stop tracking data/raw"\n                        dvc add /opt/***/data/raw &&                         git add /opt/***/data/raw.dvc &&                         git commit -m "Updated raw data version" &&                         dvc push\n                    ']
[2025-02-28T04:07:52.476+0000] {subprocess.py:86} INFO - Output:
[2025-02-28T04:07:54.141+0000] {subprocess.py:93} INFO - /opt/***/executables/data_ingestion.py:46: UserWarning: pandas only supports SQLAlchemy connectable (engine/connection) or database string URI or sqlite3 DBAPI2 connection. Other DBAPI2 objects are not tested. Please consider using SQLAlchemy.
[2025-02-28T04:07:54.141+0000] {subprocess.py:93} INFO -   data = pd.read_sql(query, connection)
[2025-02-28T04:07:54.289+0000] {subprocess.py:93} INFO - rm 'data/raw/customer_data.csv'
[2025-02-28T04:07:54.290+0000] {subprocess.py:93} INFO - rm 'data/raw/database_data.csv'
[2025-02-28T04:07:54.315+0000] {subprocess.py:93} INFO - [main 017709e] stop tracking data/raw
[2025-02-28T04:07:54.316+0000] {subprocess.py:93} INFO -  2 files changed, 20002 deletions(-)
[2025-02-28T04:07:54.316+0000] {subprocess.py:93} INFO -  delete mode 100644 data/raw/customer_data.csv
[2025-02-28T04:07:54.316+0000] {subprocess.py:93} INFO -  delete mode 100644 data/raw/database_data.csv
[2025-02-28T04:07:55.812+0000] {subprocess.py:93} INFO - 
[2025-02-28T04:07:55.813+0000] {subprocess.py:93} INFO - To track the changes with git, run:
[2025-02-28T04:07:55.813+0000] {subprocess.py:93} INFO - 
[2025-02-28T04:07:55.813+0000] {subprocess.py:93} INFO - 	git add data/.gitignore data/raw.dvc
[2025-02-28T04:07:55.814+0000] {subprocess.py:93} INFO - 
[2025-02-28T04:07:55.814+0000] {subprocess.py:93} INFO - To enable auto staging, run:
[2025-02-28T04:07:55.814+0000] {subprocess.py:93} INFO - 
[2025-02-28T04:07:55.814+0000] {subprocess.py:93} INFO - 	dvc config core.autostage true
[2025-02-28T04:07:56.107+0000] {subprocess.py:93} INFO - [main 52a8033] Updated raw data version
[2025-02-28T04:07:56.107+0000] {subprocess.py:93} INFO -  1 file changed, 6 insertions(+)
[2025-02-28T04:07:56.107+0000] {subprocess.py:93} INFO -  create mode 100644 data/raw.dvc
[2025-02-28T04:07:57.886+0000] {subprocess.py:93} INFO - ERROR: failed to push data to the cloud - config file error: no remote specified in /opt/***. Setup default remote with
[2025-02-28T04:07:57.887+0000] {subprocess.py:93} INFO -     dvc remote default <remote name>
[2025-02-28T04:07:57.887+0000] {subprocess.py:93} INFO - or use:
[2025-02-28T04:07:57.887+0000] {subprocess.py:93} INFO -     dvc <command> -r <remote name>
[2025-02-28T04:07:58.142+0000] {subprocess.py:97} INFO - Command exited with return code 1
[2025-02-28T04:07:58.169+0000] {taskinstance.py:1937} ERROR - Task failed with exception
Traceback (most recent call last):
  File "/home/airflow/.local/lib/python3.8/site-packages/airflow/operators/bash.py", line 210, in execute
    raise AirflowException(
airflow.exceptions.AirflowException: Bash command failed. The command returned a non-zero exit code 1.
[2025-02-28T04:07:58.175+0000] {taskinstance.py:1400} INFO - Marking task as FAILED. dag_id=customer_churn_ml_pipeline, task_id=data_ingestion_task, execution_date=20250228T040747, start_date=20250228T040752, end_date=20250228T040758
[2025-02-28T04:07:58.209+0000] {standard_task_runner.py:104} ERROR - Failed to execute job 22 for task data_ingestion_task (Bash command failed. The command returned a non-zero exit code 1.; 6557)
[2025-02-28T04:07:58.237+0000] {local_task_job_runner.py:228} INFO - Task exited with return code 1
[2025-02-28T04:07:58.289+0000] {taskinstance.py:2778} INFO - 0 downstream tasks scheduled from follow-on schedule check
