[2025-03-02T09:14:21.007+0000] {taskinstance.py:1159} INFO - Dependencies all met for dep_context=non-requeueable deps ti=<TaskInstance: customer_churn_ml_pipeline.data_validation_task manual__2025-03-02T09:13:54.407678+00:00 [queued]>
[2025-03-02T09:14:21.019+0000] {taskinstance.py:1159} INFO - Dependencies all met for dep_context=requeueable deps ti=<TaskInstance: customer_churn_ml_pipeline.data_validation_task manual__2025-03-02T09:13:54.407678+00:00 [queued]>
[2025-03-02T09:14:21.019+0000] {taskinstance.py:1361} INFO - Starting attempt 1 of 1
[2025-03-02T09:14:21.041+0000] {taskinstance.py:1382} INFO - Executing <Task(BashOperator): data_validation_task> on 2025-03-02 09:13:54.407678+00:00
[2025-03-02T09:14:21.047+0000] {standard_task_runner.py:57} INFO - Started process 6054 to run task
[2025-03-02T09:14:21.052+0000] {standard_task_runner.py:84} INFO - Running: ['***', 'tasks', 'run', 'customer_churn_ml_pipeline', 'data_validation_task', 'manual__2025-03-02T09:13:54.407678+00:00', '--job-id', '62', '--raw', '--subdir', 'DAGS_FOLDER/customer_churn.py', '--cfg-path', '/tmp/tmp58bv3ax3']
[2025-03-02T09:14:21.056+0000] {standard_task_runner.py:85} INFO - Job 62: Subtask data_validation_task
[2025-03-02T09:14:21.090+0000] {logging_mixin.py:154} WARNING - /home/***/.local/lib/python3.8/site-packages/***/settings.py:195 DeprecationWarning: The sql_alchemy_conn option in [core] has been moved to the sql_alchemy_conn option in [database] - the old setting has been used, but please update your config.
[2025-03-02T09:14:21.150+0000] {task_command.py:416} INFO - Running <TaskInstance: customer_churn_ml_pipeline.data_validation_task manual__2025-03-02T09:13:54.407678+00:00 [running]> on host 9113a5746a05
[2025-03-02T09:14:21.262+0000] {taskinstance.py:1662} INFO - Exporting env vars: AIRFLOW_CTX_DAG_OWNER='***' AIRFLOW_CTX_DAG_ID='customer_churn_ml_pipeline' AIRFLOW_CTX_TASK_ID='data_validation_task' AIRFLOW_CTX_EXECUTION_DATE='2025-03-02T09:13:54.407678+00:00' AIRFLOW_CTX_TRY_NUMBER='1' AIRFLOW_CTX_DAG_RUN_ID='manual__2025-03-02T09:13:54.407678+00:00'
[2025-03-02T09:14:21.263+0000] {subprocess.py:63} INFO - Tmp dir root location: /tmp
[2025-03-02T09:14:21.264+0000] {subprocess.py:75} INFO - Running command: ['/bin/bash', '-c', '\n\t\t\tcd /opt/*** &&                        dvc pull /opt/***/data/raw\n                        python /opt/***/executables/data_validation.py && \t\t\tgit add logs &&\\   \n\t\t\tgit add reports &&                        git commit -m "Updated validation" -a &&                         dvc push && git push\n                    ']
[2025-03-02T09:14:21.272+0000] {subprocess.py:86} INFO - Output:
[2025-03-02T09:14:24.354+0000] {subprocess.py:93} INFO - Everything is up to date.
[2025-03-02T09:14:25.447+0000] {subprocess.py:93} INFO - Traceback (most recent call last):
[2025-03-02T09:14:25.448+0000] {subprocess.py:93} INFO -   File "/opt/***/executables/data_validation.py", line 12, in <module>
[2025-03-02T09:14:25.448+0000] {subprocess.py:93} INFO -     logging.basicConfig(format='%(asctime)s : %(levelname)s : %(message)s', level=logging.INFO , filename=data_validation_log_file)
[2025-03-02T09:14:25.448+0000] {subprocess.py:93} INFO - NameError: name 'data_validation_log_file' is not defined
[2025-03-02T09:14:25.541+0000] {subprocess.py:93} INFO - [main 0251b45] Updated validation
[2025-03-02T09:14:25.542+0000] {subprocess.py:93} INFO -  1 file changed, 10 insertions(+)
[2025-03-02T09:14:28.966+0000] {subprocess.py:93} INFO - Everything is up to date.
[2025-03-02T09:14:30.677+0000] {subprocess.py:93} INFO - To https://github.com/anniemathew-trial/customer_churn_pipeline.git
[2025-03-02T09:14:30.678+0000] {subprocess.py:93} INFO -    604c553..0251b45  main -> main
[2025-03-02T09:14:30.692+0000] {subprocess.py:97} INFO - Command exited with return code 0
[2025-03-02T09:14:30.756+0000] {taskinstance.py:1400} INFO - Marking task as SUCCESS. dag_id=customer_churn_ml_pipeline, task_id=data_validation_task, execution_date=20250302T091354, start_date=20250302T091421, end_date=20250302T091430
[2025-03-02T09:14:30.807+0000] {local_task_job_runner.py:228} INFO - Task exited with return code 0
[2025-03-02T09:14:30.873+0000] {taskinstance.py:2778} INFO - 1 downstream tasks scheduled from follow-on schedule check
