[2025-03-03T17:06:51.424+0000] {taskinstance.py:1159} INFO - Dependencies all met for dep_context=non-requeueable deps ti=<TaskInstance: customer_churn_ml_pipeline.data_validation_task manual__2025-03-03T17:06:22.394275+00:00 [queued]>
[2025-03-03T17:06:51.436+0000] {taskinstance.py:1159} INFO - Dependencies all met for dep_context=requeueable deps ti=<TaskInstance: customer_churn_ml_pipeline.data_validation_task manual__2025-03-03T17:06:22.394275+00:00 [queued]>
[2025-03-03T17:06:51.436+0000] {taskinstance.py:1361} INFO - Starting attempt 1 of 1
[2025-03-03T17:06:51.456+0000] {taskinstance.py:1382} INFO - Executing <Task(BashOperator): data_validation_task> on 2025-03-03 17:06:22.394275+00:00
[2025-03-03T17:06:51.462+0000] {standard_task_runner.py:57} INFO - Started process 7061 to run task
[2025-03-03T17:06:51.465+0000] {standard_task_runner.py:84} INFO - Running: ['***', 'tasks', 'run', 'customer_churn_ml_pipeline', 'data_validation_task', 'manual__2025-03-03T17:06:22.394275+00:00', '--job-id', '138', '--raw', '--subdir', 'DAGS_FOLDER/customer_churn.py', '--cfg-path', '/tmp/tmp33pnt0_x']
[2025-03-03T17:06:51.468+0000] {standard_task_runner.py:85} INFO - Job 138: Subtask data_validation_task
[2025-03-03T17:06:51.492+0000] {logging_mixin.py:154} WARNING - /home/***/.local/lib/python3.8/site-packages/***/settings.py:195 DeprecationWarning: The sql_alchemy_conn option in [core] has been moved to the sql_alchemy_conn option in [database] - the old setting has been used, but please update your config.
[2025-03-03T17:06:51.543+0000] {task_command.py:416} INFO - Running <TaskInstance: customer_churn_ml_pipeline.data_validation_task manual__2025-03-03T17:06:22.394275+00:00 [running]> on host 157237bff8f7
[2025-03-03T17:06:51.673+0000] {taskinstance.py:1662} INFO - Exporting env vars: AIRFLOW_CTX_DAG_OWNER='***' AIRFLOW_CTX_DAG_ID='customer_churn_ml_pipeline' AIRFLOW_CTX_TASK_ID='data_validation_task' AIRFLOW_CTX_EXECUTION_DATE='2025-03-03T17:06:22.394275+00:00' AIRFLOW_CTX_TRY_NUMBER='1' AIRFLOW_CTX_DAG_RUN_ID='manual__2025-03-03T17:06:22.394275+00:00'
[2025-03-03T17:06:51.674+0000] {subprocess.py:63} INFO - Tmp dir root location: /tmp
[2025-03-03T17:06:51.675+0000] {subprocess.py:75} INFO - Running command: ['/bin/bash', '-c', '\n\t\t\tcd /opt/*** &&                        dvc pull /opt/***/data/raw\n                        python /opt/***/executables/data_validation.py && \t\t\tgit add logs && \\   \n\t\t\tgit add reports &&    \t\t\tgit status &&                         git commit -m "Updated validation" -a &&                         dvc push && git push\n                    ']
[2025-03-03T17:06:51.686+0000] {subprocess.py:86} INFO - Output:
[2025-03-03T17:06:55.497+0000] {subprocess.py:93} INFO - Everything is up to date.
[2025-03-03T17:06:56.919+0000] {subprocess.py:93} INFO - 2025-03-03 17:06:56,918 : INFO : Starting data validation for customer_data.csv
[2025-03-03T17:06:56.945+0000] {subprocess.py:93} INFO - 2025-03-03 17:06:56,945 : INFO : Running validation on data received from S3
[2025-03-03T17:06:57.022+0000] {subprocess.py:93} INFO - 2025-03-03 17:06:57,022 : INFO : Saving metrics to S3
[2025-03-03T17:06:57.023+0000] {subprocess.py:93} INFO - 2025-03-03 17:06:57,023 : ERROR : Error validating  data: Cannot save file into a non-existent directory: 'reports/fintech1'
[2025-03-03T17:06:57.024+0000] {subprocess.py:93} INFO - 2025-03-03 17:06:57,024 : INFO : Starting data validation for database_data.csv
[2025-03-03T17:06:57.024+0000] {subprocess.py:93} INFO - 2025-03-03 17:06:57,024 : ERROR : Error validating  data: [Errno 2] No such file or directory: '/opt/***/data/raw/fintech2/03-03-2025/database/database_data.csv'
[2025-03-03T17:06:57.224+0000] {subprocess.py:93} INFO - /bin/bash: line 3:  : command not found
[2025-03-03T17:06:57.261+0000] {subprocess.py:93} INFO - On branch main
[2025-03-03T17:06:57.261+0000] {subprocess.py:93} INFO - Your branch is up to date with 'origin/main'.
[2025-03-03T17:06:57.262+0000] {subprocess.py:93} INFO - 
[2025-03-03T17:06:57.262+0000] {subprocess.py:93} INFO - Changes to be committed:
[2025-03-03T17:06:57.263+0000] {subprocess.py:93} INFO -   (use "git restore --staged <file>..." to unstage)
[2025-03-03T17:06:57.263+0000] {subprocess.py:93} INFO - 	new file:   logs/dag_id=customer_churn_ml_pipeline/run_id=manual__2025-03-03T17:06:22.394275+00:00/task_id=data_validation_task/attempt=1.log
[2025-03-03T17:06:57.263+0000] {subprocess.py:93} INFO - 	modified:   logs/dag_id=customer_churn_ml_pipeline/run_id=manual__2025-03-03T17:06:22.394275+00:00/task_id=raw_data_storage_task/attempt=1.log
[2025-03-03T17:06:57.264+0000] {subprocess.py:93} INFO - 	modified:   logs/dag_processor_manager/dag_processor_manager.log
[2025-03-03T17:06:57.264+0000] {subprocess.py:93} INFO - 	modified:   logs/data_validation.log
[2025-03-03T17:06:57.264+0000] {subprocess.py:93} INFO - 	modified:   logs/scheduler/2025-03-03/customer_churn.py.log
[2025-03-03T17:06:57.265+0000] {subprocess.py:93} INFO - 
[2025-03-03T17:06:57.265+0000] {subprocess.py:93} INFO - Changes not staged for commit:
[2025-03-03T17:06:57.265+0000] {subprocess.py:93} INFO -   (use "git add <file>..." to update what will be committed)
[2025-03-03T17:06:57.265+0000] {subprocess.py:93} INFO -   (use "git restore <file>..." to discard changes in working directory)
[2025-03-03T17:06:57.266+0000] {subprocess.py:93} INFO - 	modified:   logs/dag_id=customer_churn_ml_pipeline/run_id=manual__2025-03-03T17:06:22.394275+00:00/task_id=data_validation_task/attempt=1.log
[2025-03-03T17:06:57.266+0000] {subprocess.py:93} INFO - 
[2025-03-03T17:06:57.266+0000] {subprocess.py:93} INFO - Untracked files:
[2025-03-03T17:06:57.266+0000] {subprocess.py:93} INFO -   (use "git add <file>..." to include in what will be committed)
[2025-03-03T17:06:57.267+0000] {subprocess.py:93} INFO - 	customer_churn_stats/feature_repo/data/online_store.db
[2025-03-03T17:06:57.267+0000] {subprocess.py:93} INFO - 	customer_churn_stats/feature_repo/data/registry.db
[2025-03-03T17:06:57.267+0000] {subprocess.py:93} INFO - 	models/
[2025-03-03T17:06:57.267+0000] {subprocess.py:93} INFO - 	online.db
[2025-03-03T17:06:57.268+0000] {subprocess.py:93} INFO - 
[2025-03-03T17:06:57.346+0000] {subprocess.py:93} INFO - [main 04fe8c9] Updated validation
[2025-03-03T17:06:57.347+0000] {subprocess.py:93} INFO -  5 files changed, 75 insertions(+)
[2025-03-03T17:06:57.347+0000] {subprocess.py:93} INFO -  create mode 100644 logs/dag_id=customer_churn_ml_pipeline/run_id=manual__2025-03-03T17:06:22.394275+00:00/task_id=data_validation_task/attempt=1.log
[2025-03-03T17:07:02.451+0000] {subprocess.py:93} INFO - Everything is up to date.
[2025-03-03T17:07:04.937+0000] {subprocess.py:93} INFO - To https://github.com/anniemathew-trial/customer_churn_pipeline.git
[2025-03-03T17:07:04.938+0000] {subprocess.py:93} INFO -    e6f8018..04fe8c9  main -> main
[2025-03-03T17:07:04.944+0000] {subprocess.py:97} INFO - Command exited with return code 0
[2025-03-03T17:07:04.979+0000] {taskinstance.py:1400} INFO - Marking task as SUCCESS. dag_id=customer_churn_ml_pipeline, task_id=data_validation_task, execution_date=20250303T170622, start_date=20250303T170651, end_date=20250303T170704
[2025-03-03T17:07:05.035+0000] {local_task_job_runner.py:228} INFO - Task exited with return code 0
[2025-03-03T17:07:05.074+0000] {taskinstance.py:2778} INFO - 1 downstream tasks scheduled from follow-on schedule check
